2025-09-30 17:03:33 [WARNING] Insert attempt with empty required fields
2025-10-01 17:13:00 [INFO] Table initialized!
2025-10-01 17:13:09 [WARNING] Insert attempt with empty required fields
2025-10-01 17:13:44 [ERROR] Insert failed: invalid input value for enum attack_enum: "syn_fl"
LINE 3:                            VALUES ('syn_fl') ON CONFLICT (na...
                                           ^
Traceback (most recent call last):
  File "C:\Users\pale_avenger\PycharmProjects\database\App.py", line 180, in insert_record
    cursor.execute("""
    ~~~~~~~~~~~~~~^^^^
                   INSERT INTO attack_name (name)
                   ^^^^^^^^^^^^^^^^^^^^^^^^^^^^^^
                   VALUES (%s) ON CONFLICT (name) DO NOTHING
                   ^^^^^^^^^^^^^^^^^^^^^^^^^^^^^^^^^^^^^^^^^
                   """, (attack_type,))
                   ^^^^^^^^^^^^^^^^^^^^
psycopg2.errors.InvalidTextRepresentation: invalid input value for enum attack_enum: "syn_fl"
LINE 3:                            VALUES ('syn_fl') ON CONFLICT (na...
                                           ^

2025-10-01 17:13:49 [INFO] Record inserted: attack_type=syn_flood, target_ip=1.1.1.1
2025-10-01 17:13:49 [INFO] Table loaded with filter=''
2025-10-01 17:14:18 [INFO] Table loaded with filter=''
2025-10-01 17:15:01 [INFO] Table loaded with filter=''
2025-10-01 17:15:35 [INFO] Table loaded with filter=''
2025-10-01 17:19:34 [ERROR] Insert failed: column "name" of relation "attack_name" does not exist
LINE 2:                            INSERT INTO attack_name (name)
                                                            ^
Traceback (most recent call last):
  File "C:\Users\pale_avenger\PycharmProjects\database\App.py", line 180, in insert_record
    cursor.execute("""
    ~~~~~~~~~~~~~~^^^^
                   INSERT INTO attack_name (name)
                   ^^^^^^^^^^^^^^^^^^^^^^^^^^^^^^
                   VALUES (%s) ON CONFLICT (name) DO NOTHING
                   ^^^^^^^^^^^^^^^^^^^^^^^^^^^^^^^^^^^^^^^^^
                   """, (attack_type,))
                   ^^^^^^^^^^^^^^^^^^^^
psycopg2.errors.UndefinedColumn: column "name" of relation "attack_name" does not exist
LINE 2:                            INSERT INTO attack_name (name)
                                                            ^

2025-10-01 17:19:41 [ERROR] Insert failed: column "name" of relation "attack_name" does not exist
LINE 2:                            INSERT INTO attack_name (name)
                                                            ^
Traceback (most recent call last):
  File "C:\Users\pale_avenger\PycharmProjects\database\App.py", line 180, in insert_record
    cursor.execute("""
    ~~~~~~~~~~~~~~^^^^
                   INSERT INTO attack_name (name)
                   ^^^^^^^^^^^^^^^^^^^^^^^^^^^^^^
                   VALUES (%s) ON CONFLICT (name) DO NOTHING
                   ^^^^^^^^^^^^^^^^^^^^^^^^^^^^^^^^^^^^^^^^^
                   """, (attack_type,))
                   ^^^^^^^^^^^^^^^^^^^^
psycopg2.errors.UndefinedColumn: column "name" of relation "attack_name" does not exist
LINE 2:                            INSERT INTO attack_name (name)
                                                            ^

2025-10-01 17:19:59 [ERROR] Insert failed: column "name" of relation "attack_name" does not exist
LINE 2:                            INSERT INTO attack_name (name)
                                                            ^
Traceback (most recent call last):
  File "C:\Users\pale_avenger\PycharmProjects\database\App.py", line 180, in insert_record
    cursor.execute("""
    ~~~~~~~~~~~~~~^^^^
                   INSERT INTO attack_name (name)
                   ^^^^^^^^^^^^^^^^^^^^^^^^^^^^^^
                   VALUES (%s) ON CONFLICT (name) DO NOTHING
                   ^^^^^^^^^^^^^^^^^^^^^^^^^^^^^^^^^^^^^^^^^
                   """, (attack_type,))
                   ^^^^^^^^^^^^^^^^^^^^
psycopg2.errors.UndefinedColumn: column "name" of relation "attack_name" does not exist
LINE 2:                            INSERT INTO attack_name (name)
                                                            ^

2025-10-01 17:20:50 [ERROR] Insert failed: column "name" of relation "attack_name" does not exist
LINE 2:                            INSERT INTO attack_name (name)
                                                            ^
Traceback (most recent call last):
  File "C:\Users\pale_avenger\PycharmProjects\database\App.py", line 180, in insert_record
    cursor.execute("""
    ~~~~~~~~~~~~~~^^^^
                   INSERT INTO attack_name (name)
                   ^^^^^^^^^^^^^^^^^^^^^^^^^^^^^^
                   VALUES (%s) ON CONFLICT (name) DO NOTHING
                   ^^^^^^^^^^^^^^^^^^^^^^^^^^^^^^^^^^^^^^^^^
                   """, (attack_type,))
                   ^^^^^^^^^^^^^^^^^^^^
psycopg2.errors.UndefinedColumn: column "name" of relation "attack_name" does not exist
LINE 2:                            INSERT INTO attack_name (name)
                                                            ^

2025-10-01 17:21:03 [ERROR] Insert failed: column "name" of relation "attack_name" does not exist
LINE 2:                            INSERT INTO attack_name (name)
                                                            ^
Traceback (most recent call last):
  File "C:\Users\pale_avenger\PycharmProjects\database\App.py", line 180, in insert_record
    cursor.execute("""
    ~~~~~~~~~~~~~~^^^^
                   INSERT INTO attack_name (name)
                   ^^^^^^^^^^^^^^^^^^^^^^^^^^^^^^
                   VALUES (%s) ON CONFLICT (name) DO NOTHING
                   ^^^^^^^^^^^^^^^^^^^^^^^^^^^^^^^^^^^^^^^^^
                   """, (attack_type,))
                   ^^^^^^^^^^^^^^^^^^^^
psycopg2.errors.UndefinedColumn: column "name" of relation "attack_name" does not exist
LINE 2:                            INSERT INTO attack_name (name)
                                                            ^

2025-10-01 17:21:14 [ERROR] Insert failed: column "name" of relation "attack_name" does not exist
LINE 2:                            INSERT INTO attack_name (name)
                                                            ^
Traceback (most recent call last):
  File "C:\Users\pale_avenger\PycharmProjects\database\App.py", line 180, in insert_record
    cursor.execute("""
    ~~~~~~~~~~~~~~^^^^
                   INSERT INTO attack_name (name)
                   ^^^^^^^^^^^^^^^^^^^^^^^^^^^^^^
                   VALUES (%s) ON CONFLICT (name) DO NOTHING
                   ^^^^^^^^^^^^^^^^^^^^^^^^^^^^^^^^^^^^^^^^^
                   """, (attack_type,))
                   ^^^^^^^^^^^^^^^^^^^^
psycopg2.errors.UndefinedColumn: column "name" of relation "attack_name" does not exist
LINE 2:                            INSERT INTO attack_name (name)
                                                            ^

2025-10-01 17:21:22 [ERROR] Insert failed: column "name" of relation "attack_name" does not exist
LINE 2:                            INSERT INTO attack_name (name)
                                                            ^
Traceback (most recent call last):
  File "C:\Users\pale_avenger\PycharmProjects\database\App.py", line 180, in insert_record
    cursor.execute("""
    ~~~~~~~~~~~~~~^^^^
                   INSERT INTO attack_name (name)
                   ^^^^^^^^^^^^^^^^^^^^^^^^^^^^^^
                   VALUES (%s) ON CONFLICT (name) DO NOTHING
                   ^^^^^^^^^^^^^^^^^^^^^^^^^^^^^^^^^^^^^^^^^
                   """, (attack_type,))
                   ^^^^^^^^^^^^^^^^^^^^
psycopg2.errors.UndefinedColumn: column "name" of relation "attack_name" does not exist
LINE 2:                            INSERT INTO attack_name (name)
                                                            ^

2025-10-01 17:22:15 [INFO] Table initialized!
2025-10-01 17:22:27 [INFO] Record inserted: attack_type=syn_flood, target_ip=1.1.1.1
2025-10-01 17:29:06 [WARNING] Insert attempt with empty required fields
2025-10-01 17:29:12 [WARNING] Insert attempt with empty required fields
2025-10-01 17:32:13 [ERROR] Insert failed: invalid input value for enum attack_enum: "syn_flood"
LINE 3:                            VALUES ('syn_flood') ON CONFLICT ...
                                           ^
Traceback (most recent call last):
  File "C:\Users\pale_avenger\PycharmProjects\database\App.py", line 180, in insert_record
    cursor.execute("""
    ~~~~~~~~~~~~~~^^^^
                   INSERT INTO attack_name (name)
                   ^^^^^^^^^^^^^^^^^^^^^^^^^^^^^^
                   VALUES (%s) ON CONFLICT (name) DO NOTHING
                   ^^^^^^^^^^^^^^^^^^^^^^^^^^^^^^^^^^^^^^^^^
                   """, (attack_type,))
                   ^^^^^^^^^^^^^^^^^^^^
psycopg2.errors.InvalidTextRepresentation: invalid input value for enum attack_enum: "syn_flood"
LINE 3:                            VALUES ('syn_flood') ON CONFLICT ...
                                           ^

2025-10-01 17:32:16 [ERROR] Insert failed: relation "attack_name" does not exist
LINE 2:                            INSERT INTO attack_name (name)
                                               ^
Traceback (most recent call last):
  File "C:\Users\pale_avenger\PycharmProjects\database\App.py", line 180, in insert_record
    cursor.execute("""
    ~~~~~~~~~~~~~~^^^^
                   INSERT INTO attack_name (name)
                   ^^^^^^^^^^^^^^^^^^^^^^^^^^^^^^
                   VALUES (%s) ON CONFLICT (name) DO NOTHING
                   ^^^^^^^^^^^^^^^^^^^^^^^^^^^^^^^^^^^^^^^^^
                   """, (attack_type,))
                   ^^^^^^^^^^^^^^^^^^^^
psycopg2.errors.UndefinedTable: relation "attack_name" does not exist
LINE 2:                            INSERT INTO attack_name (name)
                                               ^

2025-10-01 17:32:31 [INFO] Table initialized!
2025-10-01 17:32:52 [WARNING] Check constraint violation during insert
2025-10-01 18:11:35 [INFO] Table loaded with filter=''
2025-10-01 18:23:54 [WARNING] Insert attempt with empty required fields
2025-10-01 18:25:31 [ERROR] Invalid ENUM value entered: attack_type='фыв'
2025-10-01 18:25:54 [ERROR] Insert failed: null value in column "id" of relation "users" violates not-null constraint
DETAIL:  Failing row contains (null, syn_flood, 1.1.1.1, 2000-01-01 00:00:00, 123, 123, 123, t, {фвфы}).
Traceback (most recent call last):
  File "C:\Users\pale_avenger\PycharmProjects\database\App.py", line 178, in insert_record
    cursor.execute("""
    ~~~~~~~~~~~~~~^^^^
                   INSERT INTO users (attack_type, target_ip, start_time, duration_sec,
                   ^^^^^^^^^^^^^^^^^^^^^^^^^^^^^^^^^^^^^^^^^^^^^^^^^^^^^^^^^^^^^^^^^^^^
    ...<2 lines>...
                   """, (attack_type, target_ip, start_time, duration_sec, peak_dbs,
                   ^^^^^^^^^^^^^^^^^^^^^^^^^^^^^^^^^^^^^^^^^^^^^^^^^^^^^^^^^^^^^^^^^
                         source_count, is_detected, [source_country] if source_country else None))
                         ^^^^^^^^^^^^^^^^^^^^^^^^^^^^^^^^^^^^^^^^^^^^^^^^^^^^^^^^^^^^^^^^^^^^^^^^^
psycopg2.errors.NotNullViolation: null value in column "id" of relation "users" violates not-null constraint
DETAIL:  Failing row contains (null, syn_flood, 1.1.1.1, 2000-01-01 00:00:00, 123, 123, 123, t, {фвфы}).

2025-10-01 18:26:00 [ERROR] Insert failed: null value in column "id" of relation "users" violates not-null constraint
DETAIL:  Failing row contains (null, syn_flood, 1.1.1.1, 2000-01-01 00:00:00, 123, 123, 123, t, {фвфы}).
Traceback (most recent call last):
  File "C:\Users\pale_avenger\PycharmProjects\database\App.py", line 178, in insert_record
    cursor.execute("""
    ~~~~~~~~~~~~~~^^^^
                   INSERT INTO users (attack_type, target_ip, start_time, duration_sec,
                   ^^^^^^^^^^^^^^^^^^^^^^^^^^^^^^^^^^^^^^^^^^^^^^^^^^^^^^^^^^^^^^^^^^^^
    ...<2 lines>...
                   """, (attack_type, target_ip, start_time, duration_sec, peak_dbs,
                   ^^^^^^^^^^^^^^^^^^^^^^^^^^^^^^^^^^^^^^^^^^^^^^^^^^^^^^^^^^^^^^^^^
                         source_count, is_detected, [source_country] if source_country else None))
                         ^^^^^^^^^^^^^^^^^^^^^^^^^^^^^^^^^^^^^^^^^^^^^^^^^^^^^^^^^^^^^^^^^^^^^^^^^
psycopg2.errors.NotNullViolation: null value in column "id" of relation "users" violates not-null constraint
DETAIL:  Failing row contains (null, syn_flood, 1.1.1.1, 2000-01-01 00:00:00, 123, 123, 123, t, {фвфы}).

2025-10-01 18:26:18 [ERROR] Table not initialized! no schema has been selected to create in
Traceback (most recent call last):
  File "C:\Users\pale_avenger\PycharmProjects\database\App.py", line 30, in create_schema_and_tables
    cursor.execute("""
    ~~~~~~~~~~~~~~^^^^
        CREATE TYPE attack_enum AS ENUM (
        ^^^^^^^^^^^^^^^^^^^^^^^^^^^^^^^^^
    ...<28 lines>...
        );
        ^^
    """)
    ^^^^
psycopg2.errors.InvalidSchemaName: no schema has been selected to create in

2025-10-01 18:26:20 [ERROR] Table not initialized! no schema has been selected to create in
Traceback (most recent call last):
  File "C:\Users\pale_avenger\PycharmProjects\database\App.py", line 30, in create_schema_and_tables
    cursor.execute("""
    ~~~~~~~~~~~~~~^^^^
        CREATE TYPE attack_enum AS ENUM (
        ^^^^^^^^^^^^^^^^^^^^^^^^^^^^^^^^^
    ...<28 lines>...
        );
        ^^
    """)
    ^^^^
psycopg2.errors.InvalidSchemaName: no schema has been selected to create in

2025-10-01 18:26:27 [ERROR] Table not initialized! no schema has been selected to create in
Traceback (most recent call last):
  File "C:\Users\pale_avenger\PycharmProjects\database\App.py", line 30, in create_schema_and_tables
    cursor.execute("""
    ~~~~~~~~~~~~~~^^^^
        CREATE TYPE attack_enum AS ENUM (
        ^^^^^^^^^^^^^^^^^^^^^^^^^^^^^^^^^
    ...<28 lines>...
        );
        ^^
    """)
    ^^^^
psycopg2.errors.InvalidSchemaName: no schema has been selected to create in

2025-10-01 18:26:37 [ERROR] Table not initialized! no schema has been selected to create in
Traceback (most recent call last):
  File "C:\Users\pale_avenger\PycharmProjects\database\App.py", line 30, in create_schema_and_tables
    cursor.execute("""
    ~~~~~~~~~~~~~~^^^^
        CREATE TYPE attack_enum AS ENUM (
        ^^^^^^^^^^^^^^^^^^^^^^^^^^^^^^^^^
    ...<28 lines>...
        );
        ^^
    """)
    ^^^^
psycopg2.errors.InvalidSchemaName: no schema has been selected to create in

2025-10-01 18:28:13 [ERROR] Table not initialized! no schema has been selected to create in
Traceback (most recent call last):
  File "C:\Users\pale_avenger\PycharmProjects\database\App.py", line 30, in create_schema_and_tables
    cursor.execute("""
    ~~~~~~~~~~~~~~^^^^
        CREATE TYPE attack_enum AS ENUM (
        ^^^^^^^^^^^^^^^^^^^^^^^^^^^^^^^^^
    ...<28 lines>...
        );
        ^^
    """)
    ^^^^
psycopg2.errors.InvalidSchemaName: no schema has been selected to create in

2025-10-01 18:29:43 [ERROR] Table not initialized! no schema has been selected to create in
Traceback (most recent call last):
  File "C:\Users\pale_avenger\PycharmProjects\database\App.py", line 30, in create_schema_and_tables
    cursor.execute("""
    ~~~~~~~~~~~~~~^^^^
        CREATE TYPE attack_enum AS ENUM (
        ^^^^^^^^^^^^^^^^^^^^^^^^^^^^^^^^^
    ...<28 lines>...
        );
        ^^
    """)
    ^^^^
psycopg2.errors.InvalidSchemaName: no schema has been selected to create in

2025-10-01 18:29:44 [INFO] Table initialized!
2025-10-01 18:30:00 [INFO] Record inserted: attack_type=syn_flood, target_ip=1.1.1.1
2025-10-01 18:30:01 [INFO] Table loaded with filter=''
2025-10-01 18:30:16 [INFO] Record inserted: attack_type=udp_flood, target_ip=1.1.1.1
2025-10-01 18:30:18 [INFO] Table loaded with filter=''
2025-10-01 18:30:21 [INFO] Table loaded with filter='u'
2025-10-01 18:30:21 [INFO] Table loaded with filter='up'
2025-10-01 18:30:21 [INFO] Table loaded with filter='upd'
2025-10-01 18:30:22 [INFO] Table loaded with filter='up'
2025-10-01 18:30:22 [INFO] Table loaded with filter='u'
2025-10-01 18:30:23 [INFO] Table loaded with filter='ud'
2025-10-01 18:30:23 [INFO] Table loaded with filter='udp'
2025-10-01 18:30:24 [INFO] Table loaded with filter='ud'
2025-10-01 18:30:24 [INFO] Table loaded with filter='u'
2025-10-01 18:30:24 [INFO] Table loaded with filter=''
