2025-10-02 13:23:34 [ERROR] Table not initialized! 'utf-8' codec can't decode byte 0xc2 in position 61: invalid continuation byte
Traceback (most recent call last):
  File "C:\Users\ManInSpace\PycharmProjects\PythonProject\App.py", line 29, in create_schema_and_tables
    conn = get_connection()
           ^^^^^^^^^^^^^^^^
  File "C:\Users\ManInSpace\PycharmProjects\PythonProject\App.py", line 18, in get_connection
    return psycopg2.connect(
           ^^^^^^^^^^^^^^^^^
  File "C:\Users\ManInSpace\PycharmProjects\PythonProject\.venv\Lib\site-packages\psycopg2\__init__.py", line 122, in connect
    conn = _connect(dsn, connection_factory=connection_factory, **kwasync)
           ^^^^^^^^^^^^^^^^^^^^^^^^^^^^^^^^^^^^^^^^^^^^^^^^^^^^^^^^^^^^^^^
UnicodeDecodeError: 'utf-8' codec can't decode byte 0xc2 in position 61: invalid continuation byte
2025-10-02 13:25:16 [INFO] The table is already initialized!
2025-10-02 13:25:18 [INFO] Table loaded with filter=''
2025-10-02 13:25:52 [WARNING] Insert attempt with empty required fields
2025-10-02 13:26:06 [ERROR] Invalid ENUM value entered: attack_type='купкп'
2025-10-02 13:28:52 [INFO] The table is already initialized!
2025-10-02 13:31:01 [ERROR] Insert failed: name 'attack_type_edit' is not defined
Traceback (most recent call last):
  File "C:\Users\ManInSpace\PycharmProjects\PythonProject\App.py", line 152, in insert_record
    attack_type = attack_type_edit.text().strip()
                  ^^^^^^^^^^^^^^^^
NameError: name 'attack_type_edit' is not defined
2025-10-02 13:31:03 [ERROR] Insert failed: name 'attack_type_edit' is not defined
Traceback (most recent call last):
  File "C:\Users\ManInSpace\PycharmProjects\PythonProject\App.py", line 152, in insert_record
    attack_type = attack_type_edit.text().strip()
                  ^^^^^^^^^^^^^^^^
NameError: name 'attack_type_edit' is not defined
2025-10-02 13:31:55 [ERROR] Insert failed: 'QComboBox' object has no attribute 'text'
Traceback (most recent call last):
  File "C:\Users\ManInSpace\PycharmProjects\PythonProject\App.py", line 152, in insert_record
    attack_type = attack_type_combo.text().strip()
                  ^^^^^^^^^^^^^^^^^^^^^^
AttributeError: 'QComboBox' object has no attribute 'text'
2025-10-02 13:32:09 [INFO] The table is already initialized!
2025-10-02 13:32:17 [INFO] Record inserted: attack_type=syn_flood, target_ip=1.1..11
2025-10-02 13:32:19 [INFO] Table loaded with filter=''
2025-10-02 13:32:23 [INFO] The table is already initialized!
2025-10-02 13:37:45 [INFO] Record inserted: attack_type=syn_flood, target_ip=1.1.1.1
2025-10-02 13:37:47 [INFO] Table loaded with filter=''
2025-10-02 13:38:02 [INFO] Table loaded with filter=''
2025-10-02 13:38:13 [INFO] Record inserted: attack_type=syn_flood, target_ip=1.1.1.1
2025-10-02 13:38:14 [INFO] Table loaded with filter=''
2025-10-02 13:40:56 [INFO] The table is already initialized!
2025-10-02 13:41:22 [INFO] Record inserted: attack_type=syn_flood, target_ip=1.1.1.1
2025-10-02 13:41:23 [INFO] Table loaded with filter=''
2025-10-02 13:41:33 [INFO] Table loaded with filter='r'
2025-10-02 13:41:33 [INFO] Table loaded with filter='ru'
2025-10-02 13:41:34 [INFO] Table loaded with filter='rus'
2025-10-02 13:41:34 [INFO] Table loaded with filter='russ'
2025-10-02 13:41:34 [INFO] Table loaded with filter='rus'
2025-10-02 13:41:35 [INFO] Table loaded with filter='ru'
2025-10-02 13:41:35 [INFO] Table loaded with filter='r'
2025-10-02 13:41:35 [INFO] Table loaded with filter=''
2025-10-02 13:41:36 [INFO] Table loaded with filter='s'
2025-10-02 13:41:36 [INFO] Table loaded with filter='sy'
2025-10-02 13:41:37 [INFO] Table loaded with filter='syn'
2025-10-02 13:41:38 [INFO] Table loaded with filter='syn0'
2025-10-02 13:41:38 [INFO] Table loaded with filter='syn'
2025-10-02 13:41:38 [INFO] Table loaded with filter='syn)'
2025-10-02 13:41:39 [INFO] Table loaded with filter='syn)f'
2025-10-02 13:41:39 [INFO] Table loaded with filter='syn)'
2025-10-02 13:41:39 [INFO] Table loaded with filter='syn'
2025-10-02 13:41:40 [INFO] Table loaded with filter='syn_'
2025-10-02 13:41:41 [INFO] Table loaded with filter='syn_f'
2025-10-02 13:41:41 [INFO] Table loaded with filter='syn_fl'
2025-10-02 13:41:41 [INFO] Table loaded with filter='syn_flo'
2025-10-02 13:41:41 [INFO] Table loaded with filter='syn_floo'
2025-10-02 13:41:55 [INFO] Record inserted: attack_type=dns_amplification, target_ip=111.112.121.121
2025-10-02 13:41:57 [INFO] Table loaded with filter=''
2025-10-02 13:42:01 [INFO] Table loaded with filter='d'
2025-10-02 13:42:01 [INFO] Table loaded with filter='dn'
2025-10-02 13:43:43 [INFO] Record inserted: attack_type=syn_flood, target_ip=1.1.1.1
2025-10-02 13:43:47 [WARNING] Insert attempt with empty required fields
2025-10-02 13:43:51 [INFO] Record inserted: attack_type=syn_flood, target_ip=1
2025-10-02 13:43:55 [INFO] Table loaded with filter=''
2025-10-02 13:45:15 [WARNING] Insert attempt with empty required fields
2025-10-02 13:52:36 [INFO] The table is already initialized!
2025-10-02 13:54:19 [INFO] Table loaded with filter=''
2025-10-02 13:55:16 [INFO] Table initialized!
2025-10-02 13:55:17 [INFO] Table loaded with filter=''
2025-10-02 13:55:30 [INFO] Record inserted: attack_type=syn_flood, target_ip=112.121.21.212
2025-10-02 13:55:31 [INFO] Table loaded with filter=''
2025-10-02 13:56:46 [INFO] The table is already initialized!
2025-10-02 13:57:09 [INFO] Record inserted: attack_type=syn_flood, target_ip=121.12.12.121
2025-10-02 13:57:12 [INFO] Table loaded with filter=''
2025-10-02 14:05:17 [INFO] The table is already initialized!
2025-10-02 14:05:45 [INFO] Record inserted: attack_type=smurf, target_ip=121
2025-10-02 14:05:46 [INFO] Table loaded with filter=''
2025-10-04 16:52:04 [ERROR] Table not initialized! connection to server at "localhost" (::1), port 5432 failed: Permission denied (0x0000271D/10013)
	Is the server running on that host and accepting TCP/IP connections?
connection to server at "localhost" (127.0.0.1), port 5432 failed: FATAL:  password authentication failed for user "postgres"
Traceback (most recent call last):
  File "C:\Users\pale_avenger\PycharmProjects\database\src\db.py", line 29, in create_schema_and_tables
    conn = get_connection()
  File "C:\Users\pale_avenger\PycharmProjects\database\src\db.py", line 18, in get_connection
    return psycopg2.connect(
           ~~~~~~~~~~~~~~~~^
        dbname="postgres",
        ^^^^^^^^^^^^^^^^^^
    ...<3 lines>...
        port="5432"
        ^^^^^^^^^^^
    )
    ^
  File "C:\Users\pale_avenger\PycharmProjects\database\.venv\Lib\site-packages\psycopg2\__init__.py", line 135, in connect
    conn = _connect(dsn, connection_factory=connection_factory, **kwasync)
psycopg2.OperationalError: connection to server at "localhost" (::1), port 5432 failed: Permission denied (0x0000271D/10013)
	Is the server running on that host and accepting TCP/IP connections?
connection to server at "localhost" (127.0.0.1), port 5432 failed: FATAL:  password authentication failed for user "postgres"

